Workbook

Sheet Info
A1: Date | B1: Spot Date | C1: Spot | D1: First Delivery Date | E1: Days to FDD | F1: Swap Rate | G1: Swap Implied EFP | H1: Traded EFP | I1: Nearby Contract Discount/Premium EFP over Swaps | J1: $4 - 50% of Uncovered Position Outside Nearby | K1: $6 - 75% of Uncovered Position Outside Nearby | L1: $8 - 100% of Uncovered Position Outside Nearby | N1: Date | O1: Spot Date | P1: Spot | Q1: First Notice Day | R1: Days to FND | S1: Swap Rate | T1: Swap Implied EFP | U1: Traded EFP | V1: Nearby Contract/Premium EFP over Swaps | W1: 15c - Call to Assess Market Dynamics, Possible Sourcing Requirements, and Available Liquidity/Stock | X1: 20c for 5 Consecutive Business Days - 75% Cover, 50% Utilisation from 1st Active Contract | Y1: 25c for 5 Consecutive Business Days - 100% Cover, 50% Utilisation from 1st and 2nd Active Contract | Z1: Implied in Cents | AA1: EFP in cents | AB1: Discount/Prem in Cents | AE1: Gold COMEX Stocks (oz) | AF1: Gold Active Contract | AG1: Gold Aggregate OI | AH1: Gold Aggregate OI (oz) | AI1: Stock/ Agg OI | AK1: Silver COMEX Stocks ('000 oz) | AL1: Silver Active Contract | AM1: Silver OI Contract | AN1: Stocks/Agg OI | AO1: Silver COMEX Stocks | AP1: Silver OI ('000 oz) | AQ1: Silver OI (oz)
A4: 44896 | B4: {=_xll.BADDPERIODS(A4, "PER=WD", "NUMBEROFPERIODS=2", "BUSDAYADJ=-2", "CDR=GQ", "CDR=P9")} -> 44900 | C4: {=_xll.BDH("XAU Curncy","PX_LAST",A4,A4)} -> 1803.1 | D4: {=_xll.BDP("GCG23 Comdty",$M$32)} -> 01/02/2023 | E4: =_xlfn.DAYS(D4,B4) -> 58 | F4: 0.0462 | G4: =C4*(E4/360)*F4 -> 13.421074 | H4: 13.95 | I4: =H4-G4 -> 0.52892567 | J4: 4 | K4: 6 | L4: 8
A5: 44897 | B5: {=_xll.BADDPERIODS(A5, "PER=WD", "NUMBEROFPERIODS=2", "BUSDAYADJ=-2", "CDR=GQ", "CDR=P9")} -> 44901 | C5: {=_xll.BDH("XAU Curncy","PX_LAST",A5,A5)} -> 1797.63 | D5: {=_xll.BDP("GCG23 Comdty",$M$32)} -> 01/02/2023 | E5: =_xlfn.DAYS(D5,B5) -> 57 | F5: 0.046 | G5: =C5*(E5/360)*F5 -> 13.092738 | H5: 13.75 | I5: =H5-G5 -> 0.6572615 | J5: 4 | K5: 6 | L5: 8
A6: 44900 | B6: {=_xll.BADDPERIODS(A6, "PER=WD", "NUMBEROFPERIODS=2", "BUSDAYADJ=-2", "CDR=GQ", "CDR=P9")} -> 44902 | C6: {=_xll.BDH("XAU Curncy","PX_LAST",A6,A6)} -> 1768.68 | D6: {=_xll.BDP("GCG23 Comdty",$M$32)} -> 01/02/2023 | E6: =_xlfn.DAYS(D6,B6) -> 56 | F6: 0.0463 | G6: =C6*(E6/360)*F6 -> 12.738426 | H6: 12.8 | I6: =H6-G6 -> 0.0615736 | J6: 4 | K6: 6 | L6: 8
A7: 44901 | B7: {=_xll.BADDPERIODS(A7, "PER=WD", "NUMBEROFPERIODS=2", "BUSDAYADJ=-2", "CDR=GQ", "CDR=P9")} -> 44903 | C7: {=_xll.BDH("XAU Curncy","PX_LAST",A7,A7)} -> 1771.04 | D7: {=_xll.BDP("GCG23 Comdty",$M$32)} -> 01/02/2023 | E7: =_xlfn.DAYS(D7,B7) -> 55 | F7: 0.046 | G7: =C7*(E7/360)*F7 -> 12.446476 | H7: 11.9 | I7: =H7-G7 -> -0.54647556 | J7: 4 | K7: 6 | L7: 8
A8: 44902 | B8: {=_xll.BADDPERIODS(A8, "PER=WD", "NUMBEROFPERIODS=2", "BUSDAYADJ=-2", "CDR=GQ", "CDR=P9")} -> 44904 | C8: {=_xll.BDH("XAU Curncy","PX_LAST",A8,A8)} -> 1786.27 | D8: {=_xll.BDP("GCG23 Comdty",$M$32)} -> 01/02/2023 | E8: =_xlfn.DAYS(D8,B8) -> 54 | F8: 0.046 | G8: =C8*(E8/360)*F8 -> 12.325263 | H8: 12.25 | I8: =H8-G8 -> -0.075263 | J8: 4 | K8: 6 | L8: 8
A9: 44903 | B9: {=_xll.BADDPERIODS(A9, "PER=WD", "NUMBEROFPERIODS=2", "BUSDAYADJ=-2", "CDR=GQ", "CDR=P9")} -> 44907 | C9: {=_xll.BDH("XAU Curncy","PX_LAST",A9,A9)} -> 1789.14 | D9: {=_xll.BDP("GCG23 Comdty",$M$32)} -> 01/02/2023 | E9: =_xlfn.DAYS(D9,B9) -> 51 | F9: 0.0464 | G9: =C9*(E9/360)*F9 -> 11.760614 | H9: 12 | I9: =H9-G9 -> 0.2393864 | J9: 4 | K9: 6 | L9: 8
A10: 44904 | B10: {=_xll.BADDPERIODS(A10, "PER=WD", "NUMBEROFPERIODS=2", "BUSDAYADJ=-2", "CDR=GQ", "CDR=P9")} -> 44908 | C10: {=_xll.BDH("XAU Curncy","PX_LAST",A10,A10)} -> 1797.32 | D10: {=_xll.BDP("GCG23 Comdty",$M$32)} -> 01/02/2023 | E10: =_xlfn.DAYS(D10,B10) -> 50 | F10: 0.0465 | G10: =C10*(E10/360)*F10 -> 11.607692 | H10: 11.8 | I10: =H10-G10 -> 0.19230833 | J10: 4 | K10: 6 | L10: 8
A11: 44907 | B11: {=_xll.BADDPERIODS(A11, "PER=WD", "NUMBEROFPERIODS=2", "BUSDAYADJ=-2", "CDR=GQ", "CDR=P9")} -> 44909 | C11: {=_xll.BDH("XAU Curncy","PX_LAST",A11,A11)} -> 1781.44 | D11: {=_xll.BDP("GCG23 Comdty",$M$32)} -> 01/02/2023 | E11: =_xlfn.DAYS(D11,B11) -> 49 | F11: 0.0468 | G11: =C11*(E11/360)*F11 -> 11.347773 | H11: 11.4 | I11: =H11-G11 -> 0.0522272 | J11: 4 | K11: 6 | L11: 8
A12: 44908 | B12: {=_xll.BADDPERIODS(A12, "PER=WD", "NUMBEROFPERIODS=2", "BUSDAYADJ=-2", "CDR=GQ", "CDR=P9")} -> 44910 | C12: {=_xll.BDH("XAU Curncy","PX_LAST",A12,A12)} -> 1810.8 | D12: {=_xll.BDP("GCG23 Comdty",$M$32)} -> 01/02/2023 | E12: =_xlfn.DAYS(D12,B12) -> 48 | F12: 0.0468 | G12: =C12*(E12/360)*F12 -> 11.299392 | H12: 11.4 | I12: =H12-G12 -> 0.100608 | J12: 4 | K12: 6 | L12: 8
A13: 44909 | B13: {=_xll.BADDPERIODS(A13, "PER=WD", "NUMBEROFPERIODS=2", "BUSDAYADJ=-2", "CDR=GQ", "CDR=P9")} -> 44911 | C13: {=_xll.BDH("XAU Curncy","PX_LAST",A13,A13)} -> 1807.32 | D13: {=_xll.BDP("GCG23 Comdty",$M$32)} -> 01/02/2023 | E13: =_xlfn.DAYS(D13,B13) -> 47 | F13: 0.0467 | G13: =C13*(E13/360)*F13 -> 11.01913 | H13: 10.5 | I13: =H13-G13 -> -0.51912963 | J13: 4 | K13: 6 | L13: 8
A14: 44910 | B14: {=_xll.BADDPERIODS(A14, "PER=WD", "NUMBEROFPERIODS=2", "BUSDAYADJ=-2", "CDR=GQ", "CDR=P9")} -> 44914 | C14: {=_xll.BDH("XAU Curncy","PX_LAST",A14,A14)} -> 1776.85 | D14: {=_xll.BDP("GCG23 Comdty",$M$32)} -> 01/02/2023 | E14: =_xlfn.DAYS(D14,B14) -> 44 | F14: 0.0466 | G14: =C14*(E14/360)*F14 -> 10.120148 | H14: 10 | I14: =H14-G14 -> -0.12014789 | J14: 4 | K14: 6 | L14: 8
A15: 44911 | B15: {=_xll.BADDPERIODS(A15, "PER=WD", "NUMBEROFPERIODS=2", "BUSDAYADJ=-2", "CDR=GQ", "CDR=P9")} -> 44915 | C15: {=_xll.BDH("XAU Curncy","PX_LAST",A15,A15)} -> 1793.08 | D15: {=_xll.BDP("GCG23 Comdty",$M$32)} -> 01/02/2023 | E15: =_xlfn.DAYS(D15,B15) -> 43 | F15: 0.0465 | G15: =C15*(E15/360)*F15 -> 9.9590652 | H15: 9.75 | I15: =H15-G15 -> -0.20906517 | J15: 4 | K15: 6 | L15: 8
A16: 44914 | B16: {=_xll.BADDPERIODS(A16, "PER=WD", "NUMBEROFPERIODS=2", "BUSDAYADJ=-2", "CDR=GQ", "CDR=P9")} -> 44916 | C16: {=_xll.BDH("XAU Curncy","PX_LAST",A16,A16)} -> 1787.62 | D16: {=_xll.BDP("GCG23 Comdty",$M$32)} -> 01/02/2023 | E16: =_xlfn.DAYS(D16,B16) -> 42 | F16: 0.0463 | G16: =C16*(E16/360)*F16 -> 9.6561274 | H16: 9.55 | I16: =H16-G16 -> -0.10612737 | J16: 4 | K16: 6 | L16: 8
A17: 44915 | B17: {=_xll.BADDPERIODS(A17, "PER=WD", "NUMBEROFPERIODS=2", "BUSDAYADJ=-2", "CDR=GQ", "CDR=P9")} -> 44917 | C17: {=_xll.BDH("XAU Curncy","PX_LAST",A17,A17)} -> 1817.94 | D17: {=_xll.BDP("GCG23 Comdty",$M$32)} -> 01/02/2023 | E17: =_xlfn.DAYS(D17,B17) -> 41 | F17: 0.0456 | G17: =C17*(E17/360)*F17 -> 9.4411684 | H17: 9.25 | I17: =H17-G17 -> -0.1911684 | J17: 4 | K17: 6 | L17: 8 | AG17: =100 -> 100
A18: 44916 | B18: {=_xll.BADDPERIODS(A18, "PER=WD", "NUMBEROFPERIODS=2", "BUSDAYADJ=-2", "CDR=GQ", "CDR=P9")} -> 44918 | C18: {=_xll.BDH("XAU Curncy","PX_LAST",A18,A18)} -> 1814.39 | D18: {=_xll.BDP("GCG23 Comdty",$M$32)} -> 01/02/2023 | E18: =_xlfn.DAYS(D18,B18) -> 40 | F18: 0.0458 | G18: =C18*(E18/360)*F18 -> 9.2332291 | H18: 9.5 | I18: =H18-G18 -> 0.26677089 | J18: 4 | K18: 6 | L18: 8
A19: 44917 | B19: {=_xll.BADDPERIODS(A19, "PER=WD", "NUMBEROFPERIODS=2", "BUSDAYADJ=-2", "CDR=GQ", "CDR=P9")} -> 44923 | C19: {=_xll.BDH("XAU Curncy","PX_LAST",A19,A19)} -> 1792.52 | D19: {=_xll.BDP("GCG23 Comdty",$M$32)} -> 01/02/2023 | E19: =_xlfn.DAYS(D19,B19) -> 35 | F19: 0.045 | G19: =C19*(E19/360)*F19 -> 7.842275 | H19: 8.55 | I19: =H19-G19 -> 0.707725 | J19: 4 | K19: 6 | L19: 8
A20: 44918 | B20: {=_xll.BADDPERIODS(A20, "PER=WD", "NUMBEROFPERIODS=2", "BUSDAYADJ=-2", "CDR=GQ", "CDR=P9")} -> 44924 | C20: {=_xll.BDH("XAU Curncy","PX_LAST",A20,A20)} -> 1798.2 | D20: {=_xll.BDP("GCG23 Comdty",$M$32)} -> 01/02/2023 | E20: =_xlfn.DAYS(D20,B20) -> 34 | F20: 0.045 | G20: =C20*(E20/360)*F20 -> 7.64235 | H20: 8 | I20: =H20-G20 -> 0.35765 | J20: 4 | K20: 6 | L20: 8
A21: 44923 | B21: {=_xll.BADDPERIODS(A21, "PER=WD", "NUMBEROFPERIODS=2", "BUSDAYADJ=-2", "CDR=GQ", "CDR=P9")} -> 44925 | C21: {=_xll.BDH("XAU Curncy","PX_LAST",A21,A21)} -> 1804.35 | D21: {=_xll.BDP("GCG23 Comdty",$M$32)} -> 01/02/2023 | E21: =_xlfn.DAYS(D21,B21) -> 33 | F21: 0.0445 | G21: =C21*(E21/360)*F21 -> 7.3602444 | H21: 7.1 | I21: =H21-G21 -> -0.26024437 | J21: 4 | K21: 6 | L21: 8
A22: 44924 | B22: {=_xll.BADDPERIODS(A22, "PER=WD", "NUMBEROFPERIODS=2", "BUSDAYADJ=-2", "CDR=GQ", "CDR=P9")} -> 44929 | C22: {=_xll.BDH("XAU Curncy","PX_LAST",A22,A22)} -> 1814.91 | D22: {=_xll.BDP("GCG23 Comdty",$M$32)} -> 01/02/2023 | E22: =_xlfn.DAYS(D22,B22) -> 29 | F22: 0.044 | G22: =C22*(E22/360)*F22 -> 6.4328477 | H22: 6.6 | I22: =H22-G22 -> 0.16715233 | J22: 4 | K22: 6 | L22: 8
A23: 44925 | B23: {=_xll.BADDPERIODS(A23, "PER=WD", "NUMBEROFPERIODS=2", "BUSDAYADJ=-2", "CDR=GQ", "CDR=P9")} -> 44930 | C23: {=_xll.BDH("XAU Curncy","PX_LAST",A23,A23)} -> 1824.02 | D23: {=_xll.BDP("GCG23 Comdty",$M$32)} -> 01/02/2023 | E23: =_xlfn.DAYS(D23,B23) -> 28 | F23: 0.044 | G23: =C23*(E23/360)*F23 -> 6.2422018 | H23: 6.3 | I23: =H23-G23 -> 0.057798222 | J23: 4 | K23: 6 | L23: 8
A24: 44929 | B24: {=_xll.BADDPERIODS(A24, "PER=WD", "NUMBEROFPERIODS=2", "BUSDAYADJ=-2", "CDR=GQ", "CDR=P9")} -> 44931 | C24: {=_xll.BDH("XAU Curncy","PX_LAST",A24,A24)} -> 1839.48 | D24: {=_xll.BDP("GCG23 Comdty",$M$32)} -> 01/02/2023 | E24: =_xlfn.DAYS(D24,B24) -> 27 | F24: 0.044 | G24: =C24*(E24/360)*F24 -> 6.070284 | H24: 6.1 | I24: =H24-G24 -> 0.029716 | J24: 4 | K24: 6 | L24: 8 | N24: 44929 | O24: {=_xll.BADDPERIODS(N24, "PER=WD", "NUMBEROFPERIODS=2", "BUSDAYADJ=-2", "CDR=GQ", "CDR=P9")} -> 44931 | P24: {=_xll.BDH("XAG Curncy","PX_LAST",N24,N24)} -> 24.0072 | Q24: {=_xll.BDP("SIH23 Comdty",$M$32)} -> 01/03/2023 | R24: =_xlfn.DAYS(Q24,O24) -> 55 | S24: 0.0425 | T24: =P24*(R24/360)*S24 -> 0.15588008 | U24: 0.195 | V24: =100*(U24-T24) -> 3.9119917 | W24: 15 | X24: 20 | Y24: 25 | Z24: =100*T24 -> 15.588008 | AA24: =U24*100 -> 19.5 | AB24: =V24 -> 3.9119917 | AE24: {=_xll.BDH("COMXGOLD Comdty","PX_Last", N24)} -> 23179859 | AF24: {=_xll.BDS("GCA Comdty","FUT_CHAIN", "CHAIN_DATE",A24,"endrow=1")} -> GCF23 Comdty | AG24: {=_xll.BDH(AF24,"FUT_AGGTE_OPEN_INT",A24)} -> 449393 | AH24: =AG24*$AG$17 -> 44939300 | AI24: =AE24/AH24 -> 0.51580373 | AK24: {=_xll.BDH("COMXSILV Comdty","PX_Last", N24)} -> 300779.78 | AL24: {=_xll.BDS("SIA Comdty","FUT_CHAIN", "CHAIN_DATE",A24,"endrow=1")} -> SIF23 Comdty | AM24: {=_xll.BDH(AL24,"FUT_AGGTE_OPEN_INT",A24)} -> 131990 | AN24: =(AO24/AP24)/100 -> 455.76147 | AO24: =AK24*100000 -> 3.0077978e+10 | AP24: =(AM24*5000)/1000 -> 659950
A25: 44930 | B25: {=_xll.BADDPERIODS(A25, "PER=WD", "NUMBEROFPERIODS=2", "BUSDAYADJ=-2", "CDR=GQ", "CDR=P9")} -> 44932 | C25: {=_xll.BDH("XAU Curncy","PX_LAST",A25,A25)} -> 1854.56 | D25: {=_xll.BDP("GCG23 Comdty",$M$32)} -> 01/02/2023 | E25: =_xlfn.DAYS(D25,B25) -> 26 | F25: 0.0445 | G25: =C25*(E25/360)*F25 -> 5.9603498 | H25: 5.9 | I25: =H25-G25 -> -0.060349778 | J25: 4 | K25: 6 | L25: 8 | N25: 44930 | O25: {=_xll.BADDPERIODS(N25, "PER=WD", "NUMBEROFPERIODS=2", "BUSDAYADJ=-2", "CDR=GQ", "CDR=P9")} -> 44932 | P25: {=_xll.BDH("XAG Curncy","PX_LAST",N25,N25)} -> 23.7597 | Q25: {=_xll.BDP("SIH23 Comdty",$M$32)} -> 01/03/2023 | R25: =_xlfn.DAYS(Q25,O25) -> 54 | S25: 0.0425 | T25: =P25*(R25/360)*S25 -> 0.15146809 | U25: 0.1625 | V25: =100*(U25-T25) -> 1.1031913 | W25: 15 | X25: 20 | Y25: 25 | Z25: =100*T25 -> 15.146809 | AA25: =U25*100 -> 16.25 | AB25: =V25 -> 1.1031913 | AE25: {=_xll.BDH("COMXGOLD Comdty","PX_Last", N25)} -> 23179758 | AF25: {=_xll.BDS("GCA Comdty","FUT_CHAIN", "CHAIN_DATE",A25,"endrow=1")} -> GCF23 Comdty | AG25: {=_xll.BDH(AF25,"FUT_AGGTE_OPEN_INT",A25)} -> 457408 | AH25: =AG25*$AG$17 -> 45740800 | AI25: =AE25/AH25 -> 0.50676328 | AK25: {=_xll.BDH("COMXSILV Comdty","PX_Last", N25)} -> 301908.47 | AL25: {=_xll.BDS("SIA Comdty","FUT_CHAIN", "CHAIN_DATE",A25,"endrow=1")} -> SIF23 Comdty | AM25: {=_xll.BDH(AL25,"FUT_AGGTE_OPEN_INT",A25)} -> 133209 | AN25: =(AO25/AP25)/100 -> 453.28539 | AO25: =AK25*100000 -> 3.0190847e+10 | AP25: =(AM25*5000)/1000 -> 666045
A26: 44931 | B26: {=_xll.BADDPERIODS(A26, "PER=WD", "NUMBEROFPERIODS=2", "BUSDAYADJ=-2", "CDR=GQ", "CDR=P9")} -> 44935 | C26: {=_xll.BDH("XAU Curncy","PX_LAST",A26,A26)} -> 1832.89 | D26: {=_xll.BDP("GCG23 Comdty",$M$32)} -> 01/02/2023 | E26: =_xlfn.DAYS(D26,B26) -> 23 | F26: 0.0445 | G26: =C26*(E26/360)*F26 -> 5.2110081 | H26: 4.9 | I26: =H26-G26 -> -0.3110081 | J26: 4 | K26: 6 | L26: 8 | N26: 44931 | O26: {=_xll.BADDPERIODS(N26, "PER=WD", "NUMBEROFPERIODS=2", "BUSDAYADJ=-2", "CDR=GQ", "CDR=P9")} -> 44935 | P26: {=_xll.BDH("XAG Curncy","PX_LAST",N26,N26)} -> 23.2438 | Q26: {=_xll.BDP("SIH23 Comdty",$M$32)} -> 01/03/2023 | R26: =_xlfn.DAYS(Q26,O26) -> 51 | S26: 0.0425 | T26: =P26*(R26/360)*S26 -> 0.13994705 | U26: 0.14625 | V26: =100*(U26-T26) -> 0.63029542 | W26: 15 | X26: 20 | Y26: 25 | Z26: =100*T26 -> 13.994705 | AA26: =U26*100 -> 14.625 | AB26: =V26 -> 0.63029542 | AE26: {=_xll.BDH("COMXGOLD Comdty","PX_Last", N26)} -> 23171711 | AF26: {=_xll.BDS("GCA Comdty","FUT_CHAIN", "CHAIN_DATE",A26,"endrow=1")} -> GCF23 Comdty | AG26: {=_xll.BDH(AF26,"FUT_AGGTE_OPEN_INT",A26)} -> 453485 | AH26: =AG26*$AG$17 -> 45348500 | AI26: =AE26/AH26 -> 0.51096973 | AK26: {=_xll.BDH("COMXSILV Comdty","PX_Last", N26)} -> 300281.91 | AL26: {=_xll.BDS("SIA Comdty","FUT_CHAIN", "CHAIN_DATE",A26,"endrow=1")} -> SIF23 Comdty | AM26: {=_xll.BDH(AL26,"FUT_AGGTE_OPEN_INT",A26)} -> 131136 | AN26: =(AO26/AP26)/100 -> 457.97021 | AO26: =AK26*100000 -> 3.0028191e+10 | AP26: =(AM26*5000)/1000 -> 655680
A27: 44932 | B27: {=_xll.BADDPERIODS(A27, "PER=WD", "NUMBEROFPERIODS=2", "BUSDAYADJ=-2", "CDR=GQ", "CDR=P9")} -> 44936 | C27: {=_xll.BDH("XAU Curncy","PX_LAST",A27,A27)} -> 1865.69 | D27: {=_xll.BDP("GCG23 Comdty",$M$32)} -> 01/02/2023 | E27: =_xlfn.DAYS(D27,B27) -> 22 | F27: 0.0435 | G27: =C27*(E27/360)*F27 -> 4.9596259 | H27: 5 | I27: =H27-G27 -> 0.040374083 | J27: 4 | K27: 6 | L27: 8 | N27: 44932 | O27: {=_xll.BADDPERIODS(N27, "PER=WD", "NUMBEROFPERIODS=2", "BUSDAYADJ=-2", "CDR=GQ", "CDR=P9")} -> 44936 | P27: {=_xll.BDH("XAG Curncy","PX_LAST",N27,N27)} -> 23.8305 | Q27: {=_xll.BDP("SIH23 Comdty",$M$32)} -> 01/03/2023 | R27: =_xlfn.DAYS(Q27,O27) -> 50 | S27: 0.0425 | T27: =P27*(R27/360)*S27 -> 0.14066615 | U27: 0.1625 | V27: =100*(U27-T27) -> 2.1833854 | W27: 15 | X27: 20 | Y27: 25 | Z27: =100*T27 -> 14.066615 | AA27: =U27*100 -> 16.25 | AB27: =V27 -> 2.1833854 | AE27: {=_xll.BDH("COMXGOLD Comdty","PX_Last", N27)} -> 22990025 | AF27: {=_xll.BDS("GCA Comdty","FUT_CHAIN", "CHAIN_DATE",A27,"endrow=1")} -> GCF23 Comdty | AG27: {=_xll.BDH(AF27,"FUT_AGGTE_OPEN_INT",A27)} -> 463250 | AH27: =AG27*$AG$17 -> 46325000 | AI27: =AE27/AH27 -> 0.49627686 | AK27: {=_xll.BDH("COMXSILV Comdty","PX_Last", N27)} -> 300618.06 | AL27: {=_xll.BDS("SIA Comdty","FUT_CHAIN", "CHAIN_DATE",A27,"endrow=1")} -> SIF23 Comdty | AM27: {=_xll.BDH(AL27,"FUT_AGGTE_OPEN_INT",A27)} -> 132541 | AN27: =(AO27/AP27)/100 -> 453.62274 | AO27: =AK27*100000 -> 30061806000 | AP27: =(AM27*5000)/1000 -> 662705
A28: 44935 | B28: {=_xll.BADDPERIODS(A28, "PER=WD", "NUMBEROFPERIODS=2", "BUSDAYADJ=-2", "CDR=GQ", "CDR=P9")} -> 44937 | C28: {=_xll.BDH("XAU Curncy","PX_LAST",A28,A28)} -> 1871.81 | D28: {=_xll.BDP("GCG23 Comdty",$M$32)} -> 01/02/2023 | E28: =_xlfn.DAYS(D28,B28) -> 21 | F28: 0.044 | G28: =C28*(E28/360)*F28 -> 4.8043123 | H28: 4.75 | I28: =H28-G28 -> -0.054312333 | J28: 4 | K28: 6 | L28: 8 | N28: 44935 | O28: {=_xll.BADDPERIODS(N28, "PER=WD", "NUMBEROFPERIODS=2", "BUSDAYADJ=-2", "CDR=GQ", "CDR=P9")} -> 44937 | P28: {=_xll.BDH("XAG Curncy","PX_LAST",N28,N28)} -> 23.6506 | Q28: {=_xll.BDP("SIH23 Comdty",$M$32)} -> 01/03/2023 | R28: =_xlfn.DAYS(Q28,O28) -> 49 | S28: 0.0425 | T28: =P28*(R28/360)*S28 -> 0.13681215 | U28: 0.15 | V28: =100*(U28-T28) -> 1.3187849 | W28: 15 | X28: 20 | Y28: 25 | Z28: =100*T28 -> 13.681215 | AA28: =U28*100 -> 15 | AB28: =V28 -> 1.3187849 | AE28: {=_xll.BDH("COMXGOLD Comdty","PX_Last", N28)} -> 22880069 | AF28: {=_xll.BDS("GCA Comdty","FUT_CHAIN", "CHAIN_DATE",A28,"endrow=1")} -> GCF23 Comdty | AG28: {=_xll.BDH(AF28,"FUT_AGGTE_OPEN_INT",A28)} -> 476352 | AH28: =AG28*$AG$17 -> 47635200 | AI28: =AE28/AH28 -> 0.48031853 | AK28: {=_xll.BDH("COMXSILV Comdty","PX_Last", N28)} -> 299434.72 | AL28: {=_xll.BDS("SIA Comdty","FUT_CHAIN", "CHAIN_DATE",A28,"endrow=1")} -> SIF23 Comdty | AM28: {=_xll.BDH(AL28,"FUT_AGGTE_OPEN_INT",A28)} -> 132893 | AN28: =(AO28/AP28)/100 -> 450.64032 | AO28: =AK28*100000 -> 2.9943472e+10 | AP28: =(AM28*5000)/1000 -> 664465
A29: 44936 | B29: {=_xll.BADDPERIODS(A29, "PER=WD", "NUMBEROFPERIODS=2", "BUSDAYADJ=-2", "CDR=GQ", "CDR=P9")} -> 44938 | C29: {=_xll.BDH("XAU Curncy","PX_LAST",A29,A29)} -> 1877.03 | D29: {=_xll.BDP("GCG23 Comdty",$M$32)} -> 01/02/2023 | E29: =_xlfn.DAYS(D29,B29) -> 20 | F29: 0.044 | G29: =C29*(E29/360)*F29 -> 4.5882956 | H29: 4.3 | I29: =H29-G29 -> -0.28829556 | J29: 4 | K29: 6 | L29: 8 | N29: 44936 | O29: {=_xll.BADDPERIODS(N29, "PER=WD", "NUMBEROFPERIODS=2", "BUSDAYADJ=-2", "CDR=GQ", "CDR=P9")} -> 44938 | P29: {=_xll.BDH("XAG Curncy","PX_LAST",N29,N29)} -> 23.6032 | Q29: {=_xll.BDP("SIH23 Comdty",$M$32)} -> 01/03/2023 | R29: =_xlfn.DAYS(Q29,O29) -> 48 | S29: 0.0425 | T29: =P29*(R29/360)*S29 -> 0.13375147 | U29: 0.135 | V29: =100*(U29-T29) -> 0.12485333 | W29: 15 | X29: 20 | Y29: 25 | Z29: =100*T29 -> 13.375147 | AA29: =U29*100 -> 13.5 | AB29: =V29 -> 0.12485333 | AE29: {=_xll.BDH("COMXGOLD Comdty","PX_Last", N29)} -> 22996505 | AF29: {=_xll.BDS("GCA Comdty","FUT_CHAIN", "CHAIN_DATE",A29,"endrow=1")} -> GCF23 Comdty | AG29: {=_xll.BDH(AF29,"FUT_AGGTE_OPEN_INT",A29)} -> 481519 | AH29: =AG29*$AG$17 -> 48151900 | AI29: =AE29/AH29 -> 0.4775825 | AK29: {=_xll.BDH("COMXSILV Comdty","PX_Last", N29)} -> 298840.63 | AL29: {=_xll.BDS("SIA Comdty","FUT_CHAIN", "CHAIN_DATE",A29,"endrow=1")} -> SIF23 Comdty | AM29: {=_xll.BDH(AL29,"FUT_AGGTE_OPEN_INT",A29)} -> 129961 | AN29: =(AO29/AP29)/100 -> 459.89278 | AO29: =AK29*100000 -> 29884063000 | AP29: =(AM29*5000)/1000 -> 649805
A30: 44937 | B30: {=_xll.BADDPERIODS(A30, "PER=WD", "NUMBEROFPERIODS=2", "BUSDAYADJ=-2", "CDR=GQ", "CDR=P9")} -> 44939 | C30: {=_xll.BDH("XAU Curncy","PX_LAST",A30,A30)} -> 1875.69 | D30: {=_xll.BDP("GCG23 Comdty",$M$32)} -> 01/02/2023 | E30: =_xlfn.DAYS(D30,B30) -> 19 | F30: 0.044 | G30: =C30*(E30/360)*F30 -> 4.355769 | H30: 3.9 | I30: =H30-G30 -> -0.455769 | J30: 4 | K30: 6 | L30: 8 | N30: 44937 | O30: {=_xll.BADDPERIODS(N30, "PER=WD", "NUMBEROFPERIODS=2", "BUSDAYADJ=-2", "CDR=GQ", "CDR=P9")} -> 44939 | P30: {=_xll.BDH("XAG Curncy","PX_LAST",N30,N30)} -> 23.4157 | Q30: {=_xll.BDP("SIH23 Comdty",$M$32)} -> 01/03/2023 | R30: =_xlfn.DAYS(Q30,O30) -> 47 | S30: 0.0425 | T30: =P30*(R30/360)*S30 -> 0.12992461 | U30: 0.125 | V30: =100*(U30-T30) -> -0.49246132 | W30: 15 | X30: 20 | Y30: 25 | Z30: =100*T30 -> 12.992461 | AA30: =U30*100 -> 12.5 | AB30: =V30 -> -0.49246132 | AE30: {=_xll.BDH("COMXGOLD Comdty","PX_Last", N30)} -> 22996505 | AF30: {=_xll.BDS("GCA Comdty","FUT_CHAIN", "CHAIN_DATE",A30,"endrow=1")} -> GCF23 Comdty | AG30: {=_xll.BDH(AF30,"FUT_AGGTE_OPEN_INT",A30)} -> 484992 | AH30: =AG30*$AG$17 -> 48499200 | AI30: =AE30/AH30 -> 0.47416256 | AK30: {=_xll.BDH("COMXSILV Comdty","PX_Last", N30)} -> 298154.84 | AL30: {=_xll.BDS("SIA Comdty","FUT_CHAIN", "CHAIN_DATE",A30,"endrow=1")} -> SIF23 Comdty | AM30: {=_xll.BDH(AL30,"FUT_AGGTE_OPEN_INT",A30)} -> 129287 | AN30: =(AO30/AP30)/100 -> 461.22942 | AO30: =AK30*100000 -> 2.9815484e+10 | AP30: =(AM30*5000)/1000 -> 646435
A31: 44938 | B31: {=_xll.BADDPERIODS(A31, "PER=WD", "NUMBEROFPERIODS=2", "BUSDAYADJ=-2", "CDR=GQ", "CDR=P9")} -> 44943 | C31: {=_xll.BDH("XAU Curncy","PX_LAST",A31,A31)} -> 1897.09 | D31: {=_xll.BDP("GCG23 Comdty",$M$32)} -> 01/02/2023 | E31: =_xlfn.DAYS(D31,B31) -> 15 | F31: 0.044 | G31: =C31*(E31/360)*F31 -> 3.4779983 | H31: 3.05 | I31: =H31-G31 -> -0.42799833 | J31: 4 | K31: 6 | L31: 8 | M31: FUT_NOTICE_FIRST | N31: 44938 | O31: {=_xll.BADDPERIODS(N31, "PER=WD", "NUMBEROFPERIODS=2", "BUSDAYADJ=-2", "CDR=GQ", "CDR=P9")} -> 44943 | P31: {=_xll.BDH("XAG Curncy","PX_LAST",N31,N31)} -> 23.7777 | Q31: {=_xll.BDP("SIH23 Comdty",$M$32)} -> 01/03/2023 | R31: =_xlfn.DAYS(Q31,O31) -> 43 | S31: 0.0425 | T31: =P31*(R31/360)*S31 -> 0.12070485 | U31: 0.125 | V31: =100*(U31-T31) -> 0.42951479 | W31: 15 | X31: 20 | Y31: 25 | Z31: =100*T31 -> 12.070485 | AA31: =U31*100 -> 12.5 | AB31: =V31 -> 0.42951479 | AE31: {=_xll.BDH("COMXGOLD Comdty","PX_Last", N31)} -> 23000797 | AF31: {=_xll.BDS("GCA Comdty","FUT_CHAIN", "CHAIN_DATE",A31,"endrow=1")} -> GCF23 Comdty | AG31: {=_xll.BDH(AF31,"FUT_AGGTE_OPEN_INT",A31)} -> 486838 | AH31: =AG31*$AG$17 -> 48683800 | AI31: =AE31/AH31 -> 0.47245278 | AK31: {=_xll.BDH("COMXSILV Comdty","PX_Last", N31)} -> 296131.41 | AL31: {=_xll.BDS("SIA Comdty","FUT_CHAIN", "CHAIN_DATE",A31,"endrow=1")} -> SIF23 Comdty | AM31: {=_xll.BDH(AL31,"FUT_AGGTE_OPEN_INT",A31)} -> 129761 | AN31: =(AO31/AP31)/100 -> 456.42591 | AO31: =AK31*100000 -> 2.9613141e+10 | AP31: =(AM31*5000)/1000 -> 648805
A32: 44939 | B32: {=_xll.BADDPERIODS(A32, "PER=WD", "NUMBEROFPERIODS=2", "BUSDAYADJ=-2", "CDR=GQ", "CDR=P9")} -> 44944 | C32: {=_xll.BDH("XAU Curncy","PX_LAST",A32,A32)} -> 1920.23 | D32: {=_xll.BDP("GCG23 Comdty",$M$32)} -> 01/02/2023 | E32: =_xlfn.DAYS(D32,B32) -> 14 | F32: 0.044 | G32: =C32*(E32/360)*F32 -> 3.2857269 | H32: 3 | I32: =H32-G32 -> -0.28572689 | J32: 4 | K32: 6 | L32: 8 | M32: FUT_DLV_DT_FIRST | N32: 44939 | O32: {=_xll.BADDPERIODS(N32, "PER=WD", "NUMBEROFPERIODS=2", "BUSDAYADJ=-2", "CDR=GQ", "CDR=P9")} -> 44944 | P32: {=_xll.BDH("XAG Curncy","PX_LAST",N32,N32)} -> 24.2643 | Q32: {=_xll.BDP("SIH23 Comdty",$M$32)} -> 01/03/2023 | R32: =_xlfn.DAYS(Q32,O32) -> 42 | S32: 0.0425 | T32: =P32*(R32/360)*S32 -> 0.12031049 | U32: 0.1425 | V32: =100*(U32-T32) -> 2.2189512 | W32: 15 | X32: 20 | Y32: 25 | Z32: =100*T32 -> 12.031049 | AA32: =U32*100 -> 14.25 | AB32: =V32 -> 2.2189512 | AE32: {=_xll.BDH("COMXGOLD Comdty","PX_Last", N32)} -> 22781209 | AF32: {=_xll.BDS("GCA Comdty","FUT_CHAIN", "CHAIN_DATE",A32,"endrow=1")} -> GCF23 Comdty | AG32: {=_xll.BDH(AF32,"FUT_AGGTE_OPEN_INT",A32)} -> 499412 | AH32: =AG32*$AG$17 -> 49941200 | AI32: =AE32/AH32 -> 0.45616063 | AK32: {=_xll.BDH("COMXSILV Comdty","PX_Last", N32)} -> 295559.13 | AL32: {=_xll.BDS("SIA Comdty","FUT_CHAIN", "CHAIN_DATE",A32,"endrow=1")} -> SIF23 Comdty | AM32: {=_xll.BDH(AL32,"FUT_AGGTE_OPEN_INT",A32)} -> 131834 | AN32: =(AO32/AP32)/100 -> 448.38074 | AO32: =AK32*100000 -> 29555913000 | AP32: =(AM32*5000)/1000 -> 659170
A33: 44942 | B33: {=_xll.BADDPERIODS(A33, "PER=WD", "NUMBEROFPERIODS=2", "BUSDAYADJ=-2", "CDR=GQ", "CDR=P9")} -> 44944 | C33: {=_xll.BDH("XAU Curncy","PX_LAST",A33,A33)} -> 1916.02 | D33: {=_xll.BDP("GCG23 Comdty",$M$32)} -> 01/02/2023 | E33: =_xlfn.DAYS(D33,B33) -> 14 | F33: 0.044 | G33: =C33*(E33/360)*F33 -> 3.2785231 | H33: 2.9 | I33: =H33-G33 -> -0.37852311 | J33: 4 | K33: 6 | L33: 8 | N33: 44942 | O33: {=_xll.BADDPERIODS(N33, "PER=WD", "NUMBEROFPERIODS=2", "BUSDAYADJ=-2", "CDR=GQ", "CDR=P9")} -> 44944 | P33: {=_xll.BDH("XAG Curncy","PX_LAST",N33,N33)} -> 24.2545 | Q33: {=_xll.BDP("SIH23 Comdty",$M$32)} -> 01/03/2023 | R33: =_xlfn.DAYS(Q33,O33) -> 42 | S33: 0.0425 | T33: =P33*(R33/360)*S33 -> 0.1202619 | U33: 0.155 | V33: =100*(U33-T33) -> 3.4738104 | W33: 15 | X33: 20 | Y33: 25 | Z33: =100*T33 -> 12.02619 | AA33: =U33*100 -> 15.5 | AB33: =V33 -> 3.4738104 | AE33: {=_xll.BDH("COMXGOLD Comdty","PX_Last", N33)} -> #N/A N/A | AF33: {=_xll.BDS("GCA Comdty","FUT_CHAIN", "CHAIN_DATE",A33,"endrow=1")} -> GCF23 Comdty | AG33: {=_xll.BDH(AF33,"FUT_AGGTE_OPEN_INT",A33)} -> #N/A N/A | AH33: =AG33*$AG$17 -> #VALUE! | AI33: =AE33/AH33 -> #VALUE! | AK33: {=_xll.BDH("COMXSILV Comdty","PX_Last", N33)} -> #N/A N/A | AL33: {=_xll.BDS("SIA Comdty","FUT_CHAIN", "CHAIN_DATE",A33,"endrow=1")} -> SIF23 Comdty | AM33: {=_xll.BDH(AL33,"FUT_AGGTE_OPEN_INT",A33)} -> #N/A N/A | AN33: =(AO33/AP33)/100 -> #VALUE! | AO33: =AK33*100000 -> #VALUE! | AP33: =(AM33*5000)/1000 -> #VALUE!
A34: 44943 | B34: {=_xll.BADDPERIODS(A34, "PER=WD", "NUMBEROFPERIODS=2", "BUSDAYADJ=-2", "CDR=GQ", "CDR=P9")} -> 44945 | C34: {=_xll.BDH("XAU Curncy","PX_LAST",A34,A34)} -> 1908.69 | D34: {=_xll.BDP("GCG23 Comdty",$M$32)} -> 01/02/2023 | E34: =_xlfn.DAYS(D34,B34) -> 13 | F34: 0.044 | G34: =C34*(E34/360)*F34 -> 3.0326963 | H34: 2.6 | I34: =H34-G34 -> -0.43269633 | J34: 4 | K34: 6 | L34: 8 | N34: 44943 | O34: {=_xll.BADDPERIODS(N34, "PER=WD", "NUMBEROFPERIODS=2", "BUSDAYADJ=-2", "CDR=GQ", "CDR=P9")} -> 44945 | P34: {=_xll.BDH("XAG Curncy","PX_LAST",N34,N34)} -> 23.9286 | Q34: {=_xll.BDP("SIH23 Comdty",$M$32)} -> 01/03/2023 | R34: =_xlfn.DAYS(Q34,O34) -> 41 | S34: 0.0425 | T34: =P34*(R34/360)*S34 -> 0.11582107 | U34: 0.1425 | V34: =100*(U34-T34) -> 2.6678929 | W34: 15 | X34: 20 | Y34: 25 | Z34: =100*T34 -> 11.582107 | AA34: =U34*100 -> 14.25 | AB34: =V34 -> 2.6678929 | AE34: {=_xll.BDH("COMXGOLD Comdty","PX_Last", N34)} -> 22781209 | AF34: {=_xll.BDS("GCA Comdty","FUT_CHAIN", "CHAIN_DATE",A34,"endrow=1")} -> GCF23 Comdty | AG34: {=_xll.BDH(AF34,"FUT_AGGTE_OPEN_INT",A34)} -> 491818 | AH34: =AG34*$AG$17 -> 49181800 | AI34: =AE34/AH34 -> 0.46320405 | AK34: {=_xll.BDH("COMXSILV Comdty","PX_Last", N34)} -> 295343.03 | AL34: {=_xll.BDS("SIA Comdty","FUT_CHAIN", "CHAIN_DATE",A34,"endrow=1")} -> SIF23 Comdty | AM34: {=_xll.BDH(AL34,"FUT_AGGTE_OPEN_INT",A34)} -> 131862 | AN34: =(AO34/AP34)/100 -> 447.95776 | AO34: =AK34*100000 -> 2.9534303e+10 | AP34: =(AM34*5000)/1000 -> 659310
A35: 44944 | B35: {=_xll.BADDPERIODS(A35, "PER=WD", "NUMBEROFPERIODS=2", "BUSDAYADJ=-2", "CDR=GQ", "CDR=P9")} -> 44946 | C35: {=_xll.BDH("XAU Curncy","PX_LAST",A35,A35)} -> 1904.11 | D35: {=_xll.BDP("GCG23 Comdty",$M$32)} -> 01/02/2023 | E35: =_xlfn.DAYS(D35,B35) -> 12 | F35: 0.044 | G35: =C35*(E35/360)*F35 -> 2.7926947 | H35: 2 | I35: =H35-G35 -> -0.79269467 | J35: 4 | K35: 6 | L35: 8 | N35: 44944 | O35: {=_xll.BADDPERIODS(N35, "PER=WD", "NUMBEROFPERIODS=2", "BUSDAYADJ=-2", "CDR=GQ", "CDR=P9")} -> 44946 | P35: {=_xll.BDH("XAG Curncy","PX_LAST",N35,N35)} -> 23.4645 | Q35: {=_xll.BDP("SIH23 Comdty",$M$32)} -> 01/03/2023 | R35: =_xlfn.DAYS(Q35,O35) -> 40 | S35: 0.0425 | T35: =P35*(R35/360)*S35 -> 0.11080458 | U35: 0.14 | V35: =100*(U35-T35) -> 2.9195417 | W35: 15 | X35: 20 | Y35: 25 | Z35: =100*T35 -> 11.080458 | AA35: =U35*100 -> 14 | AB35: =V35 -> 2.9195417 | AE35: {=_xll.BDH("COMXGOLD Comdty","PX_Last", N35)} -> 22781209 | AF35: {=_xll.BDS("GCA Comdty","FUT_CHAIN", "CHAIN_DATE",A35,"endrow=1")} -> GCF23 Comdty | AG35: {=_xll.BDH(AF35,"FUT_AGGTE_OPEN_INT",A35)} -> 487132 | AH35: =AG35*$AG$17 -> 48713200 | AI35: =AE35/AH35 -> 0.46765988 | AK35: {=_xll.BDH("COMXSILV Comdty","PX_Last", N35)} -> 295292.22 | AL35: {=_xll.BDS("SIA Comdty","FUT_CHAIN", "CHAIN_DATE",A35,"endrow=1")} -> SIF23 Comdty | AM35: {=_xll.BDH(AL35,"FUT_AGGTE_OPEN_INT",A35)} -> 132920 | AN35: =(AO35/AP35)/100 -> 444.31571 | AO35: =AK35*100000 -> 2.9529222e+10 | AP35: =(AM35*5000)/1000 -> 664600
A36: 44945 | B36: {=_xll.BADDPERIODS(A36, "PER=WD", "NUMBEROFPERIODS=2", "BUSDAYADJ=-2", "CDR=GQ", "CDR=P9")} -> 44949 | C36: {=_xll.BDH("XAU Curncy","PX_LAST",A36,A36)} -> 1932.24 | D36: {=_xll.BDP("GCG23 Comdty",$M$32)} -> 01/02/2023 | E36: =_xlfn.DAYS(D36,B36) -> 9 | F36: 0.044 | G36: =C36*(E36/360)*F36 -> 2.125464 | H36: 1.3 | I36: =H36-G36 -> -0.825464 | J36: 4 | K36: 6 | L36: 8 | N36: 44945 | O36: {=_xll.BADDPERIODS(N36, "PER=WD", "NUMBEROFPERIODS=2", "BUSDAYADJ=-2", "CDR=GQ", "CDR=P9")} -> 44949 | P36: {=_xll.BDH("XAG Curncy","PX_LAST",N36,N36)} -> 23.8479 | Q36: {=_xll.BDP("SIH23 Comdty",$M$32)} -> 01/03/2023 | R36: =_xlfn.DAYS(Q36,O36) -> 37 | S36: 0.043 | T36: =P36*(R36/360)*S36 -> 0.10539447 | U36: 0.1225 | V36: =100*(U36-T36) -> 1.7105531 | W36: 15 | X36: 20 | Y36: 25 | Z36: =100*T36 -> 10.539447 | AA36: =U36*100 -> 12.25 | AB36: =V36 -> 1.7105531 | AE36: {=_xll.BDH("COMXGOLD Comdty","PX_Last", N36)} -> 22873418 | AF36: {=_xll.BDS("GCA Comdty","FUT_CHAIN", "CHAIN_DATE",A36,"endrow=1")} -> GCF23 Comdty | AG36: {=_xll.BDH(AF36,"FUT_AGGTE_OPEN_INT",A36)} -> 493286 | AH36: =AG36*$AG$17 -> 49328600 | AI36: =AE36/AH36 -> 0.46369486 | AK36: {=_xll.BDH("COMXSILV Comdty","PX_Last", N36)} -> 294538.59 | AL36: {=_xll.BDS("SIA Comdty","FUT_CHAIN", "CHAIN_DATE",A36,"endrow=1")} -> SIF23 Comdty | AM36: {=_xll.BDH(AL36,"FUT_AGGTE_OPEN_INT",A36)} -> 132641 | AN36: =(AO36/AP36)/100 -> 444.11395 | AO36: =AK36*100000 -> 2.9453859e+10 | AP36: =(AM36*5000)/1000 -> 663205
A37: 44946 | B37: {=_xll.BADDPERIODS(A37, "PER=WD", "NUMBEROFPERIODS=2", "BUSDAYADJ=-2", "CDR=GQ", "CDR=P9")} -> 44950 | C37: {=_xll.BDH("XAU Curncy","PX_LAST",A37,A37)} -> 1926.08 | D37: {=_xll.BDP("GCG23 Comdty",$M$32)} -> 01/02/2023 | E37: =_xlfn.DAYS(D37,B37) -> 8 | F37: 0.044 | G37: =C37*(E37/360)*F37 -> 1.8832782 | H37: 1.3 | I37: =H37-G37 -> -0.58327822 | J37: 4 | K37: 6 | L37: 8 | N37: 44946 | O37: {=_xll.BADDPERIODS(N37, "PER=WD", "NUMBEROFPERIODS=2", "BUSDAYADJ=-2", "CDR=GQ", "CDR=P9")} -> 44950 | P37: {=_xll.BDH("XAG Curncy","PX_LAST",N37,N37)} -> 23.933 | Q37: {=_xll.BDP("SIH23 Comdty",$M$32)} -> 01/03/2023 | R37: =_xlfn.DAYS(Q37,O37) -> 36 | S37: 0.043 | T37: =P37*(R37/360)*S37 -> 0.1029119 | U37: 0.12 | V37: =100*(U37-T37) -> 1.70881 | W37: 15 | X37: 20 | Y37: 25 | Z37: =100*T37 -> 10.29119 | AA37: =U37*100 -> 12 | AB37: =V37 -> 1.70881 | AE37: {=_xll.BDH("COMXGOLD Comdty","PX_Last", N37)} -> 22709480 | AF37: {=_xll.BDS("GCA Comdty","FUT_CHAIN", "CHAIN_DATE",A37,"endrow=1")} -> GCF23 Comdty | AG37: {=_xll.BDH(AF37,"FUT_AGGTE_OPEN_INT",A37)} -> 497500 | AH37: =AG37*$AG$17 -> 49750000 | AI37: =AE37/AH37 -> 0.45647196 | AK37: {=_xll.BDH("COMXSILV Comdty","PX_Last", N37)} -> 293748.81 | AL37: {=_xll.BDS("SIA Comdty","FUT_CHAIN", "CHAIN_DATE",A37,"endrow=1")} -> SIF23 Comdty | AM37: {=_xll.BDH(AL37,"FUT_AGGTE_OPEN_INT",A37)} -> 132414 | AN37: =(AO37/AP37)/100 -> 443.68241 | AO37: =AK37*100000 -> 29374881000 | AP37: =(AM37*5000)/1000 -> 662070
A38: 44949 | B38: {=_xll.BADDPERIODS(A38, "PER=WD", "NUMBEROFPERIODS=2", "BUSDAYADJ=-2", "CDR=GQ", "CDR=P9")} -> 44951 | C38: {=_xll.BDH("XAU Curncy","PX_LAST",A38,A38)} -> 1931.04 | D38: {=_xll.BDP("GCG23 Comdty",$M$32)} -> 01/02/2023 | E38: =_xlfn.DAYS(D38,B38) -> 7 | F38: 0.044 | G38: =C38*(E38/360)*F38 -> 1.652112 | H38: 1.3 | I38: =H38-G38 -> -0.352112 | J38: 4 | K38: 6 | L38: 8 | N38: 44949 | O38: {=_xll.BADDPERIODS(N38, "PER=WD", "NUMBEROFPERIODS=2", "BUSDAYADJ=-2", "CDR=GQ", "CDR=P9")} -> 44951 | P38: {=_xll.BDH("XAG Curncy","PX_LAST",N38,N38)} -> 23.458 | Q38: {=_xll.BDP("SIH23 Comdty",$M$32)} -> 01/03/2023 | R38: =_xlfn.DAYS(Q38,O38) -> 35 | S38: 0.044 | T38: =P38*(R38/360)*S38 -> 0.10034811 | U38: 0.115 | V38: =100*(U38-T38) -> 1.4651889 | W38: 15 | X38: 20 | Y38: 25 | Z38: =100*T38 -> 10.034811 | AA38: =U38*100 -> 11.5 | AB38: =V38 -> 1.4651889 | AE38: {=_xll.BDH("COMXGOLD Comdty","PX_Last", N38)} -> 22487606 | AF38: {=_xll.BDS("GCA Comdty","FUT_CHAIN", "CHAIN_DATE",A38,"endrow=1")} -> GCF23 Comdty | AG38: {=_xll.BDH(AF38,"FUT_AGGTE_OPEN_INT",A38)} -> 502492 | AH38: =AG38*$AG$17 -> 50249200 | AI38: =AE38/AH38 -> 0.44752167 | AK38: {=_xll.BDH("COMXSILV Comdty","PX_Last", N38)} -> 292740.47 | AL38: {=_xll.BDS("SIA Comdty","FUT_CHAIN", "CHAIN_DATE",A38,"endrow=1")} -> SIF23 Comdty | AM38: {=_xll.BDH(AL38,"FUT_AGGTE_OPEN_INT",A38)} -> 134669 | AN38: =(AO38/AP38)/100 -> 434.75554 | AO38: =AK38*100000 -> 2.9274047e+10 | AP38: =(AM38*5000)/1000 -> 673345
A39: 44950 | B39: {=_xll.BADDPERIODS(A39, "PER=WD", "NUMBEROFPERIODS=2", "BUSDAYADJ=-2", "CDR=GQ", "CDR=P9")} -> 44952 | C39: {=_xll.BDH("XAU Curncy","PX_LAST",A39,A39)} -> 1937.36 | D39: {=_xll.BDP("GCG23 Comdty",$M$32)} -> 01/02/2023 | E39: =_xlfn.DAYS(D39,B39) -> 6 | F39: 0.044 | G39: =C39*(E39/360)*F39 -> 1.4207307 | H39: 1 | I39: =H39-G39 -> -0.42073067 | J39: 4 | K39: 6 | L39: 8 | N39: 44950 | O39: {=_xll.BADDPERIODS(N39, "PER=WD", "NUMBEROFPERIODS=2", "BUSDAYADJ=-2", "CDR=GQ", "CDR=P9")} -> 44952 | P39: {=_xll.BDH("XAG Curncy","PX_LAST",N39,N39)} -> 23.676 | Q39: {=_xll.BDP("SIH23 Comdty",$M$32)} -> 01/03/2023 | R39: =_xlfn.DAYS(Q39,O39) -> 34 | S39: 0.043 | T39: =P39*(R39/360)*S39 -> 0.096150867 | U39: 0.1 | V39: =100*(U39-T39) -> 0.38491333 | W39: 15 | X39: 20 | Y39: 25 | Z39: =100*T39 -> 9.6150867 | AA39: =U39*100 -> 10 | AB39: =V39 -> 0.38491333 | AE39: {=_xll.BDH("COMXGOLD Comdty","PX_Last", N39)} -> 22326851 | AF39: {=_xll.BDS("GCA Comdty","FUT_CHAIN", "CHAIN_DATE",A39,"endrow=1")} -> GCF23 Comdty | AG39: {=_xll.BDH(AF39,"FUT_AGGTE_OPEN_INT",A39)} -> 499927 | AH39: =AG39*$AG$17 -> 49992700 | AI39: =AE39/AH39 -> 0.44660223 | AK39: {=_xll.BDH("COMXSILV Comdty","PX_Last", N39)} -> 292788.25 | AL39: {=_xll.BDS("SIA Comdty","FUT_CHAIN", "CHAIN_DATE",A39,"endrow=1")} -> SIF23 Comdty | AM39: {=_xll.BDH(AL39,"FUT_AGGTE_OPEN_INT",A39)} -> 134922 | AN39: =(AO39/AP39)/100 -> 434.01113 | AO39: =AK39*100000 -> 29278825000 | AP39: =(AM39*5000)/1000 -> 674610
A40: 44951 | B40: {=_xll.BADDPERIODS(A40, "PER=WD", "NUMBEROFPERIODS=2", "BUSDAYADJ=-2", "CDR=GQ", "CDR=P9")} -> 44953 | C40: {=_xll.BDH("XAU Curncy","PX_LAST",A40,A40)} -> 1946.11 | D40: {=_xll.BDP("GCG23 Comdty",$M$32)} -> 01/02/2023 | E40: =_xlfn.DAYS(D40,B40) -> 5 | F40: 0.044 | G40: =C40*(E40/360)*F40 -> 1.1892894 | H40: 0.7 | I40: =H40-G40 -> -0.48928944 | J40: 4 | K40: 6 | L40: 8 | N40: 44951 | O40: {=_xll.BADDPERIODS(N40, "PER=WD", "NUMBEROFPERIODS=2", "BUSDAYADJ=-2", "CDR=GQ", "CDR=P9")} -> 44953 | P40: {=_xll.BDH("XAG Curncy","PX_LAST",N40,N40)} -> 23.913 | Q40: {=_xll.BDP("SIH23 Comdty",$M$32)} -> 01/03/2023 | R40: =_xlfn.DAYS(Q40,O40) -> 33 | S40: 0.043 | T40: =P40*(R40/360)*S40 -> 0.094257075 | U40: 0.1 | V40: =100*(U40-T40) -> 0.5742925 | W40: 15 | X40: 20 | Y40: 25 | Z40: =100*T40 -> 9.4257075 | AA40: =U40*100 -> 10 | AB40: =V40 -> 0.5742925 | AE40: {=_xll.BDH("COMXGOLD Comdty","PX_Last", N40)} -> 22314859 | AF40: {=_xll.BDS("GCA Comdty","FUT_CHAIN", "CHAIN_DATE",A40,"endrow=1")} -> GCF23 Comdty | AG40: {=_xll.BDH(AF40,"FUT_AGGTE_OPEN_INT",A40)} -> 507068 | AH40: =AG40*$AG$17 -> 50706800 | AI40: =AE40/AH40 -> 0.44007626 | AK40: {=_xll.BDH("COMXSILV Comdty","PX_Last", N40)} -> 293182.91 | AL40: {=_xll.BDS("SIA Comdty","FUT_CHAIN", "CHAIN_DATE",A40,"endrow=1")} -> SIF23 Comdty | AM40: {=_xll.BDH(AL40,"FUT_AGGTE_OPEN_INT",A40)} -> 135090 | AN40: =(AO40/AP40)/100 -> 434.05568 | AO40: =AK40*100000 -> 2.9318291e+10 | AP40: =(AM40*5000)/1000 -> 675450
A41: 44952 | B41: {=_xll.BADDPERIODS(A41, "PER=WD", "NUMBEROFPERIODS=2", "BUSDAYADJ=-2", "CDR=GQ", "CDR=P9")} -> 44956 | C41: {=_xll.BDH("XAU Curncy","PX_LAST",A41,A41)} -> 1929.21 | D41: {=_xll.BDP("GCG23 Comdty",$M$32)} -> 01/02/2023 | E41: =_xlfn.DAYS(D41,B41) -> 2 | F41: 0.044 | G41: =C41*(E41/360)*F41 -> 0.47158467 | H41: 0.2 | I41: =H41-G41 -> -0.27158467 | J41: 4 | K41: 6 | L41: 8 | N41: 44952 | O41: {=_xll.BADDPERIODS(N41, "PER=WD", "NUMBEROFPERIODS=2", "BUSDAYADJ=-2", "CDR=GQ", "CDR=P9")} -> 44956 | P41: {=_xll.BDH("XAG Curncy","PX_LAST",N41,N41)} -> 23.9125 | Q41: {=_xll.BDP("SIH23 Comdty",$M$32)} -> 01/03/2023 | R41: =_xlfn.DAYS(Q41,O41) -> 30 | S41: 0.043 | T41: =P41*(R41/360)*S41 -> 0.085686458 | U41: 0.12 | V41: =100*(U41-T41) -> 3.4313542 | W41: 15 | X41: 20 | Y41: 25 | Z41: =100*T41 -> 8.5686458 | AA41: =U41*100 -> 12 | AB41: =V41 -> 3.4313542 | AE41: {=_xll.BDH("COMXGOLD Comdty","PX_Last", N41)} -> 22313251 | AF41: {=_xll.BDS("GCA Comdty","FUT_CHAIN", "CHAIN_DATE",A41,"endrow=1")} -> GCF23 Comdty | AG41: {=_xll.BDH(AF41,"FUT_AGGTE_OPEN_INT",A41)} -> 492098 | AH41: =AG41*$AG$17 -> 49209800 | AI41: =AE41/AH41 -> 0.45343105 | AK41: {=_xll.BDH("COMXSILV Comdty","PX_Last", N41)} -> 292767 | AL41: {=_xll.BDS("SIA Comdty","FUT_CHAIN", "CHAIN_DATE",A41,"endrow=1")} -> SIF23 Comdty | AM41: {=_xll.BDH(AL41,"FUT_AGGTE_OPEN_INT",A41)} -> 136370 | AN41: =(AO41/AP41)/100 -> 429.37156 | AO41: =AK41*100000 -> 29276700000 | AP41: =(AM41*5000)/1000 -> 681850
A42: 44953 | B42: {=_xll.BADDPERIODS(A42, "PER=WD", "NUMBEROFPERIODS=2", "BUSDAYADJ=-2", "CDR=GQ", "CDR=P9")} -> 44957 | C42: {=_xll.BDH("XAU Curncy","PX_LAST",A42,A42)} -> 1928.04 | D42: {=_xll.BDP("GCG23 Comdty",$M$32)} -> 01/02/2023 | E42: =_xlfn.DAYS(D42,B42) -> 1 | F42: 0.044 | G42: =C42*(E42/360)*F42 -> 0.23564933 | H42: 0 | I42: =H42-G42 -> -0.23564933 | J42: 4 | K42: 6 | L42: 8 | N42: 44953 | O42: {=_xll.BADDPERIODS(N42, "PER=WD", "NUMBEROFPERIODS=2", "BUSDAYADJ=-2", "CDR=GQ", "CDR=P9")} -> 44957 | P42: {=_xll.BDH("XAG Curncy","PX_LAST",N42,N42)} -> 23.604 | Q42: {=_xll.BDP("SIH23 Comdty",$M$32)} -> 01/03/2023 | R42: =_xlfn.DAYS(Q42,O42) -> 29 | S42: 0.043 | T42: =P42*(R42/360)*S42 -> 0.081761633 | U42: 0.1 | V42: =100*(U42-T42) -> 1.8238367 | W42: 15 | X42: 20 | Y42: 25 | Z42: =100*T42 -> 8.1761633 | AA42: =U42*100 -> 10 | AB42: =V42 -> 1.8238367 | AE42: {=_xll.BDH("COMXGOLD Comdty","PX_Last", N42)} -> 22313251 | AF42: {=_xll.BDS("GCA Comdty","FUT_CHAIN", "CHAIN_DATE",A42,"endrow=1")} -> GCF23 Comdty | AG42: {=_xll.BDH(AF42,"FUT_AGGTE_OPEN_INT",A42)} -> 479646 | AH42: =AG42*$AG$17 -> 47964600 | AI42: =AE42/AH42 -> 0.46520249 | AK42: {=_xll.BDH("COMXSILV Comdty","PX_Last", N42)} -> 292767 | AL42: {=_xll.BDS("SIA Comdty","FUT_CHAIN", "CHAIN_DATE",A42,"endrow=1")} -> SIF23 Comdty | AM42: {=_xll.BDH(AL42,"FUT_AGGTE_OPEN_INT",A42)} -> 136380 | AN42: =(AO42/AP42)/100 -> 429.34008 | AO42: =AK42*100000 -> 29276700000 | AP42: =(AM42*5000)/1000 -> 681900
...

Sheet Tables
A1: XAU in $ | B1: =Info!G1 -> Swap Implied EFP | C1: =Info!H1 -> Traded EFP | D1: =Info!I1 -> Nearby Contract Discount/Premium EFP over Swaps | F1: XAG in Cents | G1: =Info!T1 -> Swap Implied EFP | H1: =Info!U1 -> Traded EFP | I1: =Info!V1 -> Nearby Contract/Premium EFP over Swaps
A2: =Info!A24 -> 44929 | B2: =Info!G24 -> 6.070284 | C2: =Info!H24 -> 6.1 | D2: =Info!I24 -> 0.029716 | F2: =Info!N24 -> 44929 | G2: =100*Info!T24 -> 15.588008 | H2: =100*Info!U24 -> 19.5 | I2: =100*Info!V24 -> 391.19917
A3: =Info!A25 -> 44930 | B3: =Info!G25 -> 5.9603498 | C3: =Info!H25 -> 5.9 | D3: =Info!I25 -> -0.060349778 | F3: =Info!N25 -> 44930 | G3: =100*Info!T25 -> 15.146809 | H3: =100*Info!U25 -> 16.25 | I3: =100*Info!V25 -> 110.31913
A4: =Info!A26 -> 44931 | B4: =Info!G26 -> 5.2110081 | C4: =Info!H26 -> 4.9 | D4: =Info!I26 -> -0.3110081 | F4: =Info!N26 -> 44931 | G4: =100*Info!T26 -> 13.994705 | H4: =100*Info!U26 -> 14.625 | I4: =100*Info!V26 -> 63.029542
A5: =Info!A27 -> 44932 | B5: =Info!G27 -> 4.9596259 | C5: =Info!H27 -> 5 | D5: =Info!I27 -> 0.040374083 | F5: =Info!N27 -> 44932 | G5: =100*Info!T27 -> 14.066615 | H5: =100*Info!U27 -> 16.25 | I5: =100*Info!V27 -> 218.33854
A6: =Info!A28 -> 44935 | B6: =Info!G28 -> 4.8043123 | C6: =Info!H28 -> 4.75 | D6: =Info!I28 -> -0.054312333 | F6: =Info!N28 -> 44935 | G6: =100*Info!T28 -> 13.681215 | H6: =100*Info!U28 -> 15 | I6: =100*Info!V28 -> 131.87849
A7: =Info!A29 -> 44936 | B7: =Info!G29 -> 4.5882956 | C7: =Info!H29 -> 4.3 | D7: =Info!I29 -> -0.28829556 | F7: =Info!N29 -> 44936 | G7: =100*Info!T29 -> 13.375147 | H7: =100*Info!U29 -> 13.5 | I7: =100*Info!V29 -> 12.485333
A8: =Info!A30 -> 44937 | B8: =Info!G30 -> 4.355769 | C8: =Info!H30 -> 3.9 | D8: =Info!I30 -> -0.455769 | F8: =Info!N30 -> 44937 | G8: =100*Info!T30 -> 12.992461 | H8: =100*Info!U30 -> 12.5 | I8: =100*Info!V30 -> -49.246132
A9: =Info!A31 -> 44938 | B9: =Info!G31 -> 3.4779983 | C9: =Info!H31 -> 3.05 | D9: =Info!I31 -> -0.42799833 | F9: =Info!N31 -> 44938 | G9: =100*Info!T31 -> 12.070485 | H9: =100*Info!U31 -> 12.5 | I9: =100*Info!V31 -> 42.951479
A10: =Info!A32 -> 44939 | B10: =Info!G32 -> 3.2857269 | C10: =Info!H32 -> 3 | D10: =Info!I32 -> -0.28572689 | F10: =Info!N32 -> 44939 | G10: =100*Info!T32 -> 12.031049 | H10: =100*Info!U32 -> 14.25 | I10: =100*Info!V32 -> 221.89512
A11: =Info!A33 -> 44942 | B11: =Info!G33 -> 3.2785231 | C11: =Info!H33 -> 2.9 | D11: =Info!I33 -> -0.37852311 | F11: =Info!N33 -> 44942 | G11: =100*Info!T33 -> 12.02619 | H11: =100*Info!U33 -> 15.5 | I11: =100*Info!V33 -> 347.38104
A12: =Info!A34 -> 44943 | B12: =Info!G34 -> 3.0326963 | C12: =Info!H34 -> 2.6 | D12: =Info!I34 -> -0.43269633 | F12: =Info!N34 -> 44943 | G12: =100*Info!T34 -> 11.582107 | H12: =100*Info!U34 -> 14.25 | I12: =100*Info!V34 -> 266.78929
A13: =Info!A35 -> 44944 | B13: =Info!G35 -> 2.7926947 | C13: =Info!H35 -> 2 | D13: =Info!I35 -> -0.79269467 | F13: =Info!N35 -> 44944 | G13: =100*Info!T35 -> 11.080458 | H13: =100*Info!U35 -> 14 | I13: =100*Info!V35 -> 291.95417
... A16: =Info!A38 -> 44949 | B16: =Info!G38 -> 1.652112 | C16: =Info!H38 -> 1.3 | D16: =Info!I38 -> -0.352112 | F16: =Info!N38 -> 44949 | G16: =100*Info!T38 -> 10.034811 | H16: =100*Info!U38 -> 11.5 | I16: =100*Info!V38 -> 146.51889
